<mujoco model="boxes_free">

    <option timestep=".02"/>
    <size memory="5M"/>

    <asset>
        <!--    <texture type="skybox" builtin="gradient" rgb1="0.3 0.5 0.7" rgb2="0 0 0" width="512" height="512"/>-->
        <texture name='cube_surface' file="./iris_block.png" gridsize="3 4" gridlayout=".U..LFRB.D.."/>
        <material name="MatCube" texture="cube_surface" specular="5" shininess=".0"/>

        <texture name="texplane" type="2d" builtin="checker" rgb1=".2 .2 .2" rgb2=".15 0.15 0.15"
                 width="512" height="512" mark="cross" markrgb=".8 .8 .8"/>
        <material name="matplane" reflectance="0.3" texture="texplane" texrepeat="1 1" texuniform="true"/>
    </asset>


    <worldbody>

        <light directional="false" diffuse=".2 .2 .2" specular="0.01 0.01 0.01" pos="0 0 5.0" dir="0 0 -1"
               castshadow="false"/>
        <light directional="true" diffuse=".6 .6 .6" specular="0.0 0.0 0.0" pos="0 0 4" dir="0 0 -1"
               castshadow="false"/>


        <geom name="ground" type="plane" size="0 0 1" pos="0 0 0" quat="1 0 0 0"
              friction="0.5"
              material="matplane" condim="1"/>

        <body name="b1" pos="0.1 0 .025">
            <joint type="free"/>
            <geom name="b1" type="box" size=".025 .025 .025" rgba=".8 .2 .1 1"
                  mass="0.001"
                  friction="0.5" condim="3" material="MatCube"/>
        </body>


        <body name="b2" pos="0.0 0.04 .025">
            <joint type="free"/>
            <geom name="b2" type="box" size=".025 .025 .025" rgba=".8 .2 .1 1"
                  mass="0.001"
                  friction="0.5" condim="3" material="MatCube"/>
        </body>

        <body name="b3" pos="0.0 -0.04 .025">
            <joint type="free"/>
            <geom name="b3" type="box" size=".025 .025 .025" rgba=".8 .2 .1 1"
                  mass="0.001"
                  friction="0.5" condim="3" material="MatCube"/>
        </body>

        <body name="b4" pos="-0.1 0.08 .025">
            <joint type="free"/>
            <geom name="b4" type="box" size=".025 .025 .025" rgba=".8 .2 .1 1"
                  mass="0.001"
                  friction="0.5" condim="3" material="MatCube"/>
        </body>

        <body name="b5" pos="-0.1 0.00 .025">
            <joint type="free"/>
            <geom name="b5" type="box" size=".025 .025 .025" rgba=".8 .2 .1 1"
                  mass="0.001"
                  friction="0.5" condim="3" material="MatCube"/>
        </body>



        <body name="actor" pos="0.2 0. 0.026">
            <joint name="actor" type="slide" axis="1 0 0"/>
            <geom name="actor" type="box" size=".005 0.3 .025" rgba=".8 .8 .8 1" friction="0.0" condim="3"/>
        </body>


    </worldbody>


    <actuator>
        <position name="actor" joint="actor" kp="100" kv="5"/>
    </actuator>


</mujoco>
