<mujoco model="trifinger">

    <visual>
        <global offwidth="1280" offheight="960"/>
    </visual>

    <compiler angle="radian"/>
    <size njmax="500" nconmax="100"/>
    <asset>
        <mesh name="SIM__BL_Finger_Base" file="../assets/trifinger/finger/SIM__BL-Finger_Base.stl"/>
        <mesh name="SIM__BL_Finger_Proximal" file="../assets/trifinger/finger/SIM__BL-Finger_Proximal.stl"/>
        <mesh name="SIM__BL_Finger_Intermediate" file="../assets/trifinger/finger/SIM__BL-Finger_Intermediate.stl"/>
        <mesh name="SIM__BL_FINGER_TIP_LINK" file="../assets/trifinger/finger/SIM_BL_FINGER_TIP_LINK.stl"/>

        <texture name='cube_surface' file="../assets/textures/iris_block.png" gridsize="3 4" gridlayout=".U..LFRB.D.."/>
        <material name="obj_material" texture="cube_surface" specular="5" shininess=".0"/>

        <texture type="2d" name="groundplane" builtin="checker" mark="edge" rgb1="0.2 0.3 0.4"
                 rgb2="0.1 0.2 0.3" markrgb="0.8 0.8 0.8" width="300" height="300"/>
        <material name="groundplane" texture="groundplane" texuniform="true" texrepeat="5 5"
                  reflectance="0.0"/>
    </asset>

    <visual>
        <rgba haze="0.15 0.25 0.35 1"/>
        <quality shadowsize="8192"/>
        <global azimuth="130" elevation="-40"/>
    </visual>


    <worldbody>
        <light directional="true" ambient="0.2 0.2 0.2" diffuse="0.8 0.8 0.8" castshadow="false" pos="0 1 4"
               dir="0 0 -1" name="light0"/>
        <camera name="demo-cam"  pos="-0.005 -0.529 0.575" xyaxes="1.000 -0.002 -0.000 0.001 0.644 0.765"/>


        <!-- ============================= virtual obj ========================================= -->
        <!-- pos and quat attributes of virtual obj must be put in 'geom' -->
        <body name="goal" pos="0.0 0.0 0.03">
            <geom name="goal" size="0.030 0.030 0.030" material="obj_material" type="box" conaffinity="0" contype="0"
                  rgba="1 0  1 0.2"/>
        </body>

        <!-- ============================= real obj ========================================= -->
        <body name="obj">
            <freejoint name="obj_table"/>
            <geom name="obj" type="box" material="obj_material" size="0.03 0.03 0.03"
                  pos="0.0 0.0 0.0" quat="1 0 0 0"
                  mass="0.01"
                  condim="6"
                  friction="0.5" rgba="0 0 0 1.0"/>
        </body>

        <geom name="table" rgba="0.8 0.8 0.8 1.0" friction="0.9"
              size="0 0 0.05" type="plane" material="groundplane"
              condim="6"
        />

        <!-- =================== finger arms base =================== -->
        <geom pos="0 0.219 0.29" type="mesh" rgba="0.5 0 0 1" mesh="SIM__BL_Finger_Base"/>
        <geom pos="0.18966 -0.1095 0.29" quat="0.5 0 0 -0.866025" type="mesh" rgba="0 0.5 0 1"
              mesh="SIM__BL_Finger_Base"/>
        <geom pos="-0.18966 -0.1095 0.29" quat="-0.5 0 0 -0.866025" type="mesh" rgba="0 0.5 0.5 1"
              mesh="SIM__BL_Finger_Base"/>

        <!-- =================== arms 1 =================== -->
        <body name="finger_upper_link_0" pos="0 0.04 0.29">
            <inertial pos="0 0.06 0" quat="0.707107 0.707107 0 0" mass="0.2"
                      diaginertia="0.000353333 0.000353333 5.33333e-05"/>
            <joint name="finger_base_to_upper_joint_0" pos="0 0 0" axis="0 1 0" limited="true" range="-1.5708 1.5708"/>
            <geom pos="0 -0.02695 0" type="mesh" rgba="0.5 0 0 1" mesh="SIM__BL_Finger_Proximal"/>
            <body name="finger_middle_link_0" pos="0 0 0">
                <inertial pos="0.028 0 -0.08" mass="0.2" diaginertia="0.000353333 0.000353333 5.33333e-05"/>
                <joint name="finger_upper_to_middle_joint_0" pos="0 0 0" axis="-1 0 0" limited="true"
                       range="-1.35263 4.49422"/>
                <geom pos="0.014 0 0" quat="0.707107 0.707107 0 0" type="mesh" rgba="0.5 0 0 1"
                      mesh="SIM__BL_Finger_Intermediate"/>
                <body name="finger_lower_link_0" pos="0 0 -0.16">
                    <inertial pos="0 0 -0.126667" mass="0.03" diaginertia="8.36667e-05 8.36667e-05 1e-06"/>
                    <joint name="finger_middle_to_lower_joint_0" pos="0 0 0" axis="1 0 0" limited="true"
                           range="-3.00197 3.00197"/>
                    <geom name="fingertip_0" friction="0.9 0.005 0.0001" pos="0.014 0 0" quat="0.707107 0.707107 0 0"
                          type="mesh" rgba="0.5 0 0 1" mesh="SIM__BL_FINGER_TIP_LINK"/>
                    <site rgba="0.5 0.0 0.0 1" size="0.001" pos="0 0 -0.16" name="fingertip_0"/>
                </body>
            </body>
        </body>

        <!-- =================== arms 2 =================== -->
        <body name="finger_upper_link_120" pos="0.034641 -0.02 0.29" quat="0.5 0 0 -0.866025">
            <inertial pos="0 0.06 0" quat="0.707107 0.707107 0 0" mass="0.2"
                      diaginertia="0.000353333 0.000353333 5.33333e-05"/>
            <joint name="finger_base_to_upper_joint_120" pos="0 0 0" axis="0 1 0" limited="true"
                   range="-1.5708 1.5708"/>
            <geom pos="0 -0.02695 0" type="mesh" rgba="0 0.5 0 1" mesh="SIM__BL_Finger_Proximal"/>
            <body name="finger_middle_link_120" pos="0 0 0">
                <inertial pos="0.028 0 -0.08" mass="0.2" diaginertia="0.000353333 0.000353333 5.33333e-05"/>
                <joint name="finger_upper_to_middle_joint_120" pos="0 0 0" axis="-1 0 0" limited="true"
                       range="-1.35263 4.49422"/>
                <geom pos="0.014 0 0" quat="0.707107 0.707107 0 0" type="mesh" rgba="0 0.5 0 1"
                      mesh="SIM__BL_Finger_Intermediate"/>
                <body name="finger_lower_link_120" pos="0 0 -0.16">
                    <inertial pos="0 0 -0.126667" mass="0.03" diaginertia="8.36667e-05 8.36667e-05 1e-06"/>
                    <joint name="finger_middle_to_lower_joint_120" pos="0 0 0" axis="1 0 0" limited="true"
                           range="-3.00197 3.00197"/>
                    <geom name="fingertip_120" friction="0.9 0.005 0.0001" pos="0.014 0 0" quat="0.707107 0.707107 0 0"
                          type="mesh" rgba="0 0.5 0 1" mesh="SIM__BL_FINGER_TIP_LINK"/>
                    <site rgba="0.0 0.5 0.00 1" size="0.001" pos="0 0 -0.16" name="fingertip_120"/>
                </body>
            </body>
        </body>

        <!-- =================== arms 3 =================== -->
        <body name="finger_upper_link_240" pos="-0.034641 -0.02 0.29" quat="-0.5 0 0 -0.866025">
            <inertial pos="0 0.06 0" quat="0.707107 0.707107 0 0" mass="0.2"
                      diaginertia="0.000353333 0.000353333 5.33333e-05"/>
            <joint name="finger_base_to_upper_joint_240" pos="0 0 0" axis="0 1 0" limited="true"
                   range="-1.5708 1.5708"/>
            <geom pos="0 -0.02695 0" type="mesh" rgba="0 0.5 0.5 1" mesh="SIM__BL_Finger_Proximal"/>
            <body name="finger_middle_link_240" pos="0 0 0">
                <inertial pos="0.028 0 -0.08" mass="0.2" diaginertia="0.000353333 0.000353333 5.33333e-05"/>
                <joint name="finger_upper_to_middle_joint_240" pos="0 0 0" axis="-1 0 0" limited="true"
                       range="-1.35263 4.49422"/>
                <geom pos="0.014 0 0" quat="0.707107 0.707107 0 0" type="mesh" rgba="0 0.5 0.5 1"
                      mesh="SIM__BL_Finger_Intermediate"/>
                <body name="finger_lower_link_240" pos="0 0 -0.16">
                    <inertial pos="0 0 -0.126667" mass="0.03" diaginertia="8.36667e-05 8.36667e-05 1e-06"/>
                    <joint name="finger_middle_to_lower_joint_240" pos="0 0 0" axis="1 0 0" limited="true"
                           range="-3.00197 3.00197"/>
                    <geom name="fingertip_240" friction="0.9 0.005 0.0001" pos="0.014 0 0" quat="0.707107 0.707107 0 0"
                          type="mesh" rgba="0 0.5 0.5 1" mesh="SIM__BL_FINGER_TIP_LINK"/>
                    <site rgba="0.0 0.0 0.5 1" size="0.001" pos="0 0 -0.16" name="fingertip_240"/>
                </body>
            </body>
        </body>

    </worldbody>

    <actuator>
        <!--          <position name="finger_base_to_upper_joint_0" joint="finger_base_to_upper_joint_0"  kp="100" kv="0.1"/>-->
        <!--          <position name="finger_upper_to_middle_joint_0" joint="finger_upper_to_middle_joint_0" kp="100" kv="0.1"/>-->
        <!--          <position name="finger_middle_to_lower_joint_0" joint="finger_middle_to_lower_joint_0"  kp="100" kv="0.1"/>-->
        <!--          <position name="finger_base_to_upper_joint_120" joint="finger_base_to_upper_joint_120"  kp="10" kv="0.1"/>-->
        <!--          <position name="finger_upper_to_middle_joint_120" joint="finger_upper_to_middle_joint_120"  kp="10" kv="0.1"/>-->
        <!--          <position name="finger_middle_to_lower_joint_120" joint="finger_middle_to_lower_joint_120"  kp="10" kv="0.1"/>-->
        <!--          <position name="finger_base_to_upper_joint_240" joint="finger_base_to_upper_joint_240"  kp="100" kv="0.1"/>-->
        <!--          <position name="finger_upper_to_middle_joint_240" joint="finger_upper_to_middle_joint_240"  kp="100" kv="0.1"/>-->
        <!--          <position name="finger_middle_to_lower_joint_240" joint="finger_middle_to_lower_joint_240"  kp="100" kv="0.1"/>-->

        <motor name="finger_base_to_upper_joint_0" joint="finger_base_to_upper_joint_0"/>
        <motor name="finger_upper_to_middle_joint_0" joint="finger_upper_to_middle_joint_0"/>
        <motor name="finger_middle_to_lower_joint_0" joint="finger_middle_to_lower_joint_0"/>
        <motor name="finger_base_to_upper_joint_120" joint="finger_base_to_upper_joint_120"/>
        <motor name="finger_upper_to_middle_joint_120" joint="finger_upper_to_middle_joint_120"/>
        <motor name="finger_middle_to_lower_joint_120" joint="finger_middle_to_lower_joint_120"/>
        <motor name="finger_base_to_upper_joint_240" joint="finger_base_to_upper_joint_240"/>
        <motor name="finger_upper_to_middle_joint_240" joint="finger_upper_to_middle_joint_240"/>
        <motor name="finger_middle_to_lower_joint_240" joint="finger_middle_to_lower_joint_240"/>
    </actuator>
</mujoco>
